Workbook

Sheet primary_studies
A1: ID | B1: TITLE | C1: AUTHORS | D1: YEAR | E1: DOI
A2: P01 | B2: Sustainability Design and Software: The Karlskrona Manifesto | C2: Christoph Becker, Ruzanna Chitchyan, Leticia Duboc, Steve Easterbrook, Birgit Penzenstadler, Norbert Seyff, Colin C. Venters | D2: 2015 | E2: 10.1109/icse.2015.179
A3: P02 | B3: Interdisciplinary Design Patterns for Socially Aware Computing | C3: Harun Baraki, Kurt Geihs, Christian Voigtmann, Axel Hoffmann, Romy Kniewel, Bjo ̈rn-Elmar Macek and Julia Zirfas | D3: 2015 | E3: 10.1109/icse-seis.2019.00010
A4: P03 | B4: The role of design thinking and physical prototyping in social software engineering | C4: Peter Newman, Maria Angela Ferrario, Will Simm, Stephen Forshaw, Adrian Friday, Jon Whittle | D4: 2015 | E4: 10.1145/2889160.2889219
A5: P04 | B5: On the role of value sensitive concerns in software engineering practice | C5: Balbir Barn, Ravinder Barn, Franco Raimondi​ | D5: 2015 | E5: 10.1145/3183428.3183437
A6: P05 | B6: Engineering sustainability through language | C6: Ruzanna Chitchyan, Walter Cazzola, Awais Rashid​​ | D6: 2015 | E6: 10.1109/icse-seis.2019.00015
A7: P06 | B7: Enabling the definition and enforcement of governance rules in open source systems | C7: Javier Luis Cánovas Izquierdo, Jordi Cabot | D7: 2015 | E7: 10.1145/3183428.3183436
A8: P07 | B8: AppCivist: a service-oriented software platform for socially sustainable activism | C8: Animesh Pathak, Valerie Issarny, James Holston​ | D8: 2015
A9: P08 | B9: SOA4DM: applying an SOA paradigm to coordination in humanitarian disaster response | C9: Kelly Lyons, Christie Oh | D9: 2015 | E9: 10.1109/icse-seis.2019.00014
A10: P09 | B10: Managing emergent ethical concerns for software engineering in society | C10: Awais Rashid, Karenza Moore, Corinne May-Chahal, Ruzanna Chitchyan | D10: 2015 | E10: 10.1109/icse.2015.181
A11: P10 | B11: Dementia and social sustainability: challenges for software engineering | C11: Alistair Sutcliffe, Paul Rayson, Chris Bull, Pete Sawyer | D11: 2015 | E11: 10.1109/icse-seis.2017.2
A12: P11 | B12: Cognitively sustainable ICT with ubiquitous mobile services: challenges and opportunities | C12: Marcus Jägemar, Gordana Dodig Crnkovic​ | D12: 2015 | E12: 10.1109/icse-seis.2017.3
A13: P12 | B13: Software energy profiling: comparing releases of a software product | C13: Erik A. Jagroep, Jan Martijn van der Werf, Giuseppe Procaccianti, Patricia Lago, Sjaak Brinkkemper, Leen Blom, Rob van Vliet | D13: 2016 | E13: 10.1145/3377815.3381377
A14: P13 | B14: Sustainability design in requirements engineering: state of practice | C14: Ruzanna Chitchyan, Walter Cazzola, Awais Rashid | D14: 2016 | E14: 10.1109/icse-seis52602.2021.00012
A15: P14 | B15: Sustainability debt: a portfolio-based approach for evaluating sustainability requirements in architectures | C15: Javier Garbajosa, José Ángel Sanz, Mikael Svahnberg, Jan Bosch | D15: 2016 | E15: 10.1109/icse-seis.2019.00012
A16: P15 | B16: Values-first SE: research principles in practice | C16: Maria Paasivaara, Casper Lassenius, Steven Fraser, Jürgen Münch, Kari Systä | D16: 2016 | E16: 10.1145/2889160.2889216
A17: P16 | B17: A guided tour of the legal implications of software cloning | C17: Paolo Ciancarini, Daniel Russo, Alberto Sillitti, Giancarlo Succi | D17: 2016 | E17: 10.1109/icse-seis.2019.00011
A18: P17 | B18: Engineering software assemblies for participatory democracy: the participatory budgeting use case | C18: James Holston, Valérie Issarny, Cristhian Parra | D18: 2016 | E18: 10.1109/icse-seis.2017.8
A19: P18 | B19: Software engineering and policy | C19: Anthony Finkelstein | D19: 2016 | E19: 10.1145/3183428.3183434
A20: P19 | B20: Characterising Sustainability Requirements: A New Species Red Herring or Just an Odd Fish? | C20: Colin C. Venters, Norbert Seyff, Christoph Becker, Stefanie Betz, Ruzanna Chitchyan, Leticia Duboc, Dan McIntyre, Birgit Penzenstadler | D20: 2017 | E20: 10.1145/2889160.2889221
... A124: P123 | B124: What Can Requirements Engineering Do for Emerging System of Systems? Case of Smart Local Energy | C124: R. Chitchyan | D124: 2024 | E124: 10.1145/3639475.3640108

Sheet citation_data
A1: ID | B1: TITLE | C1: YEAR | D1: DOI | E1: CITATIONS (SORTED)
A2: P01 | B2: Sustainability Design and Software: The Karlskrona Manifesto | C2: 2015 | D2: 10.1109/icse.2015.179 | E2: 130
A3: P40 | B3: Gender Diversity and Women in Software Teams: How Do They Affect Community Smells? | C3: 2019 | D3: 10.1109/icse-seis.2019.00010 | E3: 87
A4: P15 | B4: Values-first SE: research principles in practice | C4: 2016 | D4: 10.1145/2889160.2889219 | E4: 38
A5: P38 | B5: Competence-Confidence Gap: A Threat to Female Developers' Contribution on GitHub | C5: 2018 | D5: 10.1145/3183428.3183437 | E5: 33
A6: P45 | B6: Architecture Design Decision Maps for Software Sustainability | C6: 2019 | D6: 10.1109/icse-seis.2019.00015 | E6: 29
A7: P30 | B7: User Feedback in the App Store: A Cross-Cultural Study | C7: 2018 | D7: 10.1145/3183428.3183436 | E7: 28
A8: P57 | B8: Society-Oriented Applications Development: Investigating Users' Values from Bangladeshi Agriculture Mobile Applications | C8: 2020 | D8: 10.1145/3377815.3381382 | E8: 28
A9: P44 | B9: Beyond the Code Itself: How Programmers Really Look at Pull Requests | C9: 2019 | D9: 10.1109/icse-seis.2019.00014 | E9: 26
A10: P03 | B10: The role of design thinking and physical prototyping in social software engineering | C10: 2015 | D10: 10.1109/icse.2015.181 | E10: 21
A11: P19 | B11: Characterising Sustainability Requirements: A New Species Red Herring or Just an Odd Fish? | C11: 2017 | D11: 10.1109/icse-seis.2017.2 | E11: 21
A12: P20 | B12: Privacy Requirements: Present & Future | C12: 2017 | D12: 10.1109/icse-seis.2017.3 | E12: 21
A13: P55 | B13: Is Using Deep Learning Frameworks Free? Characterizing Technical Debt in Deep Learning Frameworks | C13: 2020 | D13: 10.1145/3377815.3381377 | E13: 21
... A124: P123 | B124: What Can Requirements Engineering Do for Emerging System of Systems? Case of Smart Local Energy | C124: 2024 | D124: 10.1145/3639475.3640108 | E124: 0

Sheet citation_pivot_table
A1: Year | B1: Citations
A2: 2015 | B2: 198
A3: 2016 | B3: 88
A4: 2017 | B4: 91
A5: 2018 | B5: 130
A6: 2019 | B6: 181
A7: 2020 | B7: 100
A8: 2021 | B8: 83
A9: 2022 | B9: 48
A10: 2023 | B10: 33
A11: 2024 | B11: 8
A12: (blank)
A13: Grand Total | B13: 960

Sheet research_type
A1: ID | B1: TITLE | C1: AUTHORS | D1: YEAR | E1: TYPE | F1: REASON | H1: Total Papers | I1: Type | J1: 2015 | K1: 2016 | L1: 2017 | M1: 2018 | N1: 2019 | O1: 2020 | P1: 2021 | Q1: 2022 | R1: 2023 | S1: 2024
A2: P01 | B2: Sustainability Design and Software: The Karlskrona Manifesto | C2: Christoph Becker, Ruzanna Chitchyan, Leticia Duboc, Steve Easterbrook, Birgit Penzenstadler, Norbert Seyff, Colin C. Venters | D2: 2015 | E2: Evaluation Research | F2: Assesses the acceptance and efficacy of green software engineering methods, classifying it as evaluation research. | H2: 46 | I2: Evaluation Research | J2: =COUNTIFS(E:E, I2,D:D,$J$1) -> 4 | K2: =COUNTIFS(E:E, I2,D:D,$K$1) -> 2 | L2: =COUNTIFS(E:E, I2,D:D,$L$1) -> 4 | M2: =COUNTIFS(E:E, I2,D:D,$M$1) -> 5 | N2: =COUNTIFS(E:E, I2,D:D,$N$1) -> 2 | O2: =COUNTIFS(E:E, I2,D:D,$O$1) -> 3 | P2: =COUNTIFS(E:E, I2,D:D,$P$1) -> 2 | Q2: =COUNTIFS(E:E, I2,D:D,$Q$1) -> 7 | R2: =COUNTIFS(E:E, I2,D:D,$R$1) -> 5 | S2: =COUNTIFS(E:E, I2,D:D,$S$1) -> 13
A3: P02 | B3: Interdisciplinary Design Patterns for Socially Aware Computing | C3: Harun Baraki, Kurt Geihs, Christian Voigtmann, Axel Hoffmann, Romy Kniewel, Bjo ̈rn-Elmar Macek and Julia Zirfas | D3: 2015 | E3: Proposal of Solution | F3: Provides design patterns for incorporating social awareness into computing systems, hence proposing a solution. | H3: 38 | I3: Proposal of Solution | J3: =COUNTIFS(E:E, I3,D:D,$J$1) -> 5 | K3: =COUNTIFS(E:E, I3,D:D,$K$1) -> 1 | L3: =COUNTIFS(E:E, I3,D:D,$L$1) -> 3 | M3: =COUNTIFS(E:E, I3,D:D,$M$1) -> 4 | N3: =COUNTIFS(E:E, I3,D:D,$N$1) -> 2 | O3: =COUNTIFS(E:E, I3,D:D,$O$1) -> 2 | P3: =COUNTIFS(E:E, I3,D:D,$P$1) -> 5 | Q3: =COUNTIFS(E:E, I3,D:D,$Q$1) -> 5 | R3: =COUNTIFS(E:E, I3,D:D,$R$1) -> 6 | S3: 5
A4: P03 | B4: The role of design thinking and physical prototyping in social software engineering | C4: Peter Newman, Maria Angela Ferrario, Will Simm, Stephen Forshaw, Adrian Friday, Jon Whittle | D4: 2015 | E4: Evaluation Research | F4: This paper evaluates the impact of software engineering practices on many areas of sustainability, and it is classified as evaluation research. | H4: 5 | I4: Opinion Paper | J4: =COUNTIFS(E:E, I4,D:D,$J$1) -> 1 | K4: =COUNTIFS(E:E, I4,D:D,$K$1) -> 1 | L4: =COUNTIFS(E:E, I4,D:D,$L$1) -> 0 | M4: =COUNTIFS(E:E, I4,D:D,$M$1) -> 0 | N4: =COUNTIFS(E:E, I4,D:D,$N$1) -> 0 | O4: =COUNTIFS(E:E, I4,D:D,$O$1) -> 1 | P4: =COUNTIFS(E:E, I4,D:D,$P$1) -> 0 | Q4: =COUNTIFS(E:E, I4,D:D,$Q$1) -> 2 | R4: =COUNTIFS(E:E, I4,D:D,$R$1) -> 0 | S4: 0
A5: P04 | B5: On the role of value sensitive concerns in software engineering practice | C5: Balbir Barn, Ravinder Barn, Franco Raimondi​ | D5: 2015 | E5: Evaluation Research | F5: This article analyzes the role of value-sensitive issues in software engineering practice. It falls under evaluation research because it investigates a problem in practice and its implications. | H5: 10 | I5: Philosophical Paper | J5: =COUNTIFS(E:E, I5,D:D,$J$1) -> 1 | K5: =COUNTIFS(E:E, I5,D:D,$K$1) -> 2 | L5: =COUNTIFS(E:E, I5,D:D,$L$1) -> 0 | M5: =COUNTIFS(E:E, I5,D:D,$M$1) -> 0 | N5: =COUNTIFS(E:E, I5,D:D,$N$1) -> 1 | O5: =COUNTIFS(E:E, I5,D:D,$O$1) -> 1 | P5: =COUNTIFS(E:E, I5,D:D,$P$1) -> 2 | Q5: =COUNTIFS(E:E, I5,D:D,$Q$1) -> 1 | R5: =COUNTIFS(E:E, I5,D:D,$R$1) -> 2 | S5: 0
A6: P05 | B6: Engineering sustainability through language | C6: Ruzanna Chitchyan, Walter Cazzola, Awais Rashid​​ | D6: 2015 | E6: Proposal of Solution | F6: This paper proposes introducing sustainability considerations into programming languages as a solution. | H6: 18 | I6: Validation Research | J6: =COUNTIFS(E:E, I6,D:D,$J$1) -> 0 | K6: =COUNTIFS(E:E, I6,D:D,$K$1) -> 1 | L6: =COUNTIFS(E:E, I6,D:D,$L$1) -> 1 | M6: =COUNTIFS(E:E, I6,D:D,$M$1) -> 2 | N6: =COUNTIFS(E:E, I6,D:D,$N$1) -> 1 | O6: =COUNTIFS(E:E, I6,D:D,$O$1) -> 4 | P6: =COUNTIFS(E:E, I6,D:D,$P$1) -> 2 | Q6: =COUNTIFS(E:E, I6,D:D,$Q$1) -> 2 | R6: =COUNTIFS(E:E, I6,D:D,$R$1) -> 4 | S6: 1
A7: P06 | B7: Enabling the definition and enforcement of governance rules in open source systems | C7: Javier Luis Cánovas Izquierdo, Jordi Cabot | D7: 2015 | E7: Proposal of Solution | F7: This document proposes a governance framework for sustainable software engineering and serves as a solution. | H7: 6 | I7: Personal Experience Paper | J7: =COUNTIFS(E:E, I7,D:D,$J$1) -> 0 | K7: =COUNTIFS(E:E, I7,D:D,$K$1) -> 0 | L7: =COUNTIFS(E:E, I7,D:D,$L$1) -> 1 | M7: =COUNTIFS(E:E, I7,D:D,$M$1) -> 1 | N7: =COUNTIFS(E:E, I7,D:D,$N$1) -> 0 | O7: =COUNTIFS(E:E, I7,D:D,$O$1) -> 1 | P7: =COUNTIFS(E:E, I7,D:D,$P$1) -> 0 | Q7: =COUNTIFS(E:E, I7,D:D,$Q$1) -> 0 | R7: =COUNTIFS(E:E, I7,D:D,$R$1) -> 3 | S7: 0
A8: P07 | B8: AppCivist: a service-oriented software platform for socially sustainable activism | C8: Animesh Pathak, Valerie Issarny, James Holston​ | D8: 2015 | E8: Proposal of Solution | F8: This paper proposes a solution for allowing social activism using service-oriented architecture. | H8: =SUM(J8:S8) -> 114 | J8: =SUM(J2:J7) -> 11 | K8: 7 | L8: =COUNTIFS(G:G, K8,F:F,$L$1) -> 0 | M8: 12 | N8: 6 | O8: 12 | P8: 11 | Q8: 17 | R8: 20 | S8: 18
A9: P08 | B9: SOA4DM: applying an SOA paradigm to coordination in humanitarian disaster response | C9: Kelly Lyons, Christie Oh | D9: 2015 | E9: Proposal of Solution | F9: This work provides an innovative approach for disaster management coordination, which is classified as a solution proposal.
A10: P09 | B10: Managing emergent ethical concerns for software engineering in society | C10: Awais Rashid, Karenza Moore, Corinne May-Chahal, Ruzanna Chitchyan | D10: 2015 | E10: Evaluation Research | F10: This evaluation research article focuses on addressing emerging ethical dilemmas in software engineering and presents iterative frameworks based on real-world projects.
A11: P10 | B11: Dementia and social sustainability: challenges for software engineering | C11: Alistair Sutcliffe, Paul Rayson, Chris Bull, Pete Sawyer | D11: 2015 | E11: Opinion Paper | F11: This is an opinion piece that discusses the junction of dementia care and software engineering.
A12: P11 | B12: Cognitively sustainable ICT with ubiquitous mobile services: challenges and opportunities | C12: Marcus Jägemar, Gordana Dodig Crnkovic​ | D12: 2015 | E12: Philosophical Paper | F12: Discusses difficulties and provides new frameworks for sustainable ICT; classified as a philosophical article.
A13: P12 | B13: Software energy profiling: comparing releases of a software product | C13: Erik A. Jagroep, Jan Martijn van der Werf, Giuseppe Procaccianti, Patricia Lago, Sjaak Brinkkemper, Leen Blom, Rob van Vliet | D13: 2016 | E13: Validation Research | F13: Examines the properties of a suggested solution and classifies it as validation research.
A14: P13 | B14: Sustainability design in requirements engineering: state of practice | C14: Ruzanna Chitchyan, Walter Cazzola, Awais Rashid | D14: 2016 | E14: Evaluation Research | F14: This study evaluates current sustainable design approaches in requirements engineering, making it an assessment research work.
A15: P14 | B15: Sustainability debt: a portfolio-based approach for evaluating sustainability requirements in architectures | C15: Javier Garbajosa, José Ángel Sanz, Mikael Svahnberg, Jan Bosch | D15: 2016 | E15: Proposal of Solution | F15: Offers a solution for evaluating sustainability requirements, hence proposing a solution.
A16: P15 | B16: Values-first SE: research principles in practice | C16: Maria Paasivaara, Casper Lassenius, Steven Fraser, Jürgen Münch, Kari Systä | D16: 2016 | E16: Philosophical Paper | F16: This paper is a philosophical study that examines the role of values in software engineering.
A17: P16 | B17: A guided tour of the legal implications of software cloning | C17: Paolo Ciancarini, Daniel Russo, Alberto Sillitti, Giancarlo Succi | D17: 2016 | E17: Philosophical Paper | F17: Discusses legal implications and frameworks, which fall under the area of philosophical papers.
A18: P17 | B18: Engineering software assemblies for participatory democracy: the participatory budgeting use case | C18: James Holston, Valérie Issarny, Cristhian Parra | D18: 2016 | E18: Evaluation Research | F18: Evaluates a practical application of participatory democracy and classifies it as evaluation research.
A19: P18 | B19: Software engineering and policy | C19: Anthony Finkelstein | D19: 2016 | E19: Opinion Paper | F19: Provides thoughts on the role of software engineering in policy formulation, falling under the category of opinion paper.
A20: P19 | B20: Characterising Sustainability Requirements: A New Species Red Herring or Just an Odd Fish? | C20: Colin C. Venters, Norbert Seyff, Christoph Becker, Stefanie Betz, Ruzanna Chitchyan, Leticia Duboc, Dan McIntyre, Birgit Penzenstadler | D20: 2017 | E20: Evaluation Research | F20: Evaluates sustainable design methods in software architecture, which falls under the topic of evaluation research.
... A124: P123 | B124: What Can Requirements Engineering Do for Emerging System of Systems? Case of Smart Local Energy | C124: R. Chitchyan | D124: 2024 | E124: Evaluation Research | F124: case study

Sheet keywords_data
A1: ID | B1: TITLE | C1: AUTHORS | D1: YEAR | E1: KEYWORDS | F1: SOURCE
A2: P01 | B2: Sustainability Design and Software: The Karlskrona Manifesto | C2: Christoph Becker, Ruzanna Chitchyan, Leticia Duboc, Steve Easterbrook, Birgit Penzenstadler, Norbert Seyff, Colin C. Venters | D2: 2015 | E2: Sustainability, Cross-disciplinary Initiative, Current Practice and Future Steps, Karlskrona Manifesto for Sustainability Design ,Software Engineering | F2: No, Absract
A3: P02 | B3: Interdisciplinary Design Patterns for Socially Aware Computing | C3: Harun Baraki, Kurt Geihs, Christian Voigtmann, Axel Hoffmann, Romy Kniewel, Bjo ̈rn-Elmar Macek and Julia Zirfas | D3: 2015 | E3: Design Patterns, Interdisciplinary, Social Compatibility, User Acceptance, Legal Compliance | F3: No, Absract
A4: P03 | B4: The role of design thinking and physical prototyping in social software engineering | C4: Peter Newman, Maria Angela Ferrario, Will Simm, Stephen Forshaw, Adrian Friday, Jon Whittle | D4: 2015 | E4: Social Software Engineering, Agile Approach, Physical Design, Renewable Energy | F4: No, Absract
A5: P04 | B5: On the role of value sensitive concerns in software engineering practice | C5: Balbir Barn, Ravinder Barn, Franco Raimondi​ | D5: 2015 | E5: Value Sensitive Design, Values, Co-Design, Requirements elicitation, Societal sustainability, Software engineering practice | F5: Yes, +Abstract
A6: P05 | B6: Engineering sustainability through language | C6: Ruzanna Chitchyan, Walter Cazzola, Awais Rashid​​ | D6: 2015 | E6: Sustainability, Programming Language, proof-of-concept, Micro-languages | F6: No, Absract
A7: P06 | B7: Enabling the definition and enforcement of governance rules in open source systems | C7: Javier Luis Cánovas Izquierdo, Jordi Cabot | D7: 2015 | E7: Governance Rules, Long-term Sustainability, Open Source Software (OSS), Mylyn | F7: No, Absract
A8: P07 | B8: AppCivist: a service-oriented software platform for socially sustainable activism | C8: Animesh Pathak, Valerie Issarny, James Holston​ | D8: 2015 | E8: ICT, Social Activism, Mobile Devices and Social Networking, Software Architectures, Interdisciplinary Research | F8: No, Absract
A9: P08 | B9: SOA4DM: applying an SOA paradigm to coordination in humanitarian disaster response | C9: Kelly Lyons, Christie Oh | D9: 2015 | E9: Service-Oriented Architecture (SOA), Disaster response, Crisis management, Resource management, Ethical Concerns | F9: Yes, +Abstract
A10: P09 | B10: Managing emergent ethical concerns for software engineering in society | C10: Awais Rashid, Karenza Moore, Corinne May-Chahal, Ruzanna Chitchyan | D10: 2015 | E10: Software Engineering, Ethics, Framework, Social Responsibility, Iterative Process | F10: No, Absract
A11: P10 | B11: Dementia and social sustainability: challenges for software engineering | C11: Alistair Sutcliffe, Paul Rayson, Chris Bull, Pete Sawyer | D11: 2015 | E11: Dementia, Software Engineering, Social Sustainability, Tailored Solutions, Quality of Life | F11: Yes, +Abstract
A12: P11 | B12: Cognitively sustainable ICT with ubiquitous mobile services: challenges and opportunities | C12: Marcus Jägemar, Gordana Dodig Crnkovic​ | D12: 2015 | E12: Cognitive sustainability, Social sustainability, Sustainable ICT, Cognitive revolution, Privacy, Shared attention, Social cognition, Software engineering for social good | F12: Yes
A13: P12 | B13: Software energy profiling: comparing releases of a software product | C13: Erik A. Jagroep, Jan Martijn van der Werf, Giuseppe Procaccianti, Patricia Lago, Sjaak Brinkkemper, Leen Blom, Rob van Vliet | D13: 2016 | E13: Energy Efficiency, Profiling, Software Architecture, Software, ICT Product, Experimentation, Measurement, Performance | F13: Yes, +Abstract
... A124: P123 | B124: What Can Requirements Engineering Do for Emerging System of Systems? Case of Smart Local Energy | C124: R. Chitchyan | D124: 2024 | E124: System-of-systems,Requirements engineering,case study,smart energy system,virtual system-of-systems,systems transition,energy transition | F124: Yes

Sheet keyword_id_mapping
A1: ID | B1: KEYWORDS
A2: P01 | B2: sustainability, cross-disciplinary initiative, current practice and future steps, karlskrona manifesto for sustainability design ,software engineering
A3: P02 | B3: design patterns, interdisciplinary, social compatibility, user acceptance, legal compliance
A4: P03 | B4: social software engineering, agile approach, physical design, renewable energy
A5: P04 | B5: value sensitive design, values, co-design, requirements elicitation, societal sustainability, software engineering practice
A6: P05 | B6: sustainability, programming language, proof-of-concept, micro-languages
A7: P06 | B7: governance rules, long-term sustainability, open source software (oss), mylyn
A8: P07 | B8: ict, social activism, mobile devices and social networking, software architectures, interdisciplinary research
A9: P08 | B9: service-oriented architecture (soa), disaster response, crisis management, resource management, ethical concerns
A10: P09 | B10: software engineering, ethics, framework, social responsibility, iterative process
A11: P10 | B11: dementia, software engineering, social sustainability, tailored solutions, quality of life
A12: P11 | B12: cognitive sustainability, social sustainability, sustainable ict, cognitive revolution, privacy, shared attention, social cognition, software engineering for social good
... A124: P123 | B124: system-of-systems,requirements engineering,case study,smart energy system,virtual system-of-systems,systems transition,energy transition

Sheet keyword_clusters
A1: Cluster | B1: Keywords | C1: Unique IDs | D1: Unique ID Count | E1: Keyword Count
A2: 5 | B2: Software Engineering, Software engineering practice, Software Engineering, Software Engineering, software engineering, Software Engineering, Software engineering, Software engineering, Software Engineering, Software Engineering Processes, software engineering, Software engineering, Software engineering education, Software engineering, Software Engineering, Software engineering, Software engineering, Software Engineering, software engineering, Software Engineering, Software Engineering, software engineering, Software Engineering, Software Engineering, software engineering, software engineering | C2: P01, P04, P09, P10, P14, P18, P27, P33, P34, P43, P47, P54, P58, P59, P70, P71, P78, P88, P89, P97, P99, P100, P114, P115, P116, P122 | D2: 26 | E2: 26 | G2: Keyword Category | H2: Total Keywords | I2: Study IDs
A3: 33 | B3: Sustainability, Societal sustainability, Sustainability, Long-term Sustainability, Social Sustainability, Cognitive sustainability, Social sustainability, Sustainability, Sustainability Design, Sustainability, sustainability debt, Sustainability, Sustainability Requirement, Sustainability, Sustainability, sustainability, environmental sustainability | C3: P01, P04, P05, P06, P10, P11, P13, P14, P19, P45, P54, P116, P118 | D3: 13 | E3: 17 | G3: Sustainability | H3: 17 | I3: P01, P04, P05, P06, P10, P11, P13, P14, P19, P45, P54, P116, P118
A4: 45 | B4: Diversity, Diversity, Diversity, diversity, Diversity, diversity, Diversity, Diversity, Diversity Awareness, Gender Diversity, diversity, Diversity | C4: P71, P77, P81, P85, P88, P90, P91, P96, P104, P108, P111 | D4: 11 | E4: 12 | G4: Diversity | H4: 12 | I4: P71, P77, P81, P85, P88, P90, P91, P96, P104, P108, P111
A5: 100 | B5: Open Source Software (OSS), Open Source Software Engineering, Open Source Software, Free/Open Source Software (FOSS), Open-Source Software, Open-Source Software Analysis, Open source Software development, Open source software, Open Source Software, Open-source Software | C5: P06, P21, P28, P29, P44, P72, P81, P104 | D5: 8 | E5: 10 | G5: Open Source Software | H5: 10 | I5: P06, P21, P28, P29, P44, P72, P81, P104
A6: 35 | B6: System Development, Software Development History, Software development, Software development, Freelance software development, Software Development, software development, software development teams, software development, software development | C6: P19, P28, P60, P76, P87, P94, P100, P108, P112, P120 | D6: 10 | E6: 10 | G6: Software Development | H6: 10 | I6: P19, P28, P60, P76, P87, P94, P100, P108, P112, P120
A7: 7 | B7: Inclusion, Inclusion, inclusion, Inclusion, inclusion, Inclusion | C7: P71, P80, P90, P91, P108, P111 | D7: 6 | E7: 6 | G7: Inclusion | H7: 6 | I7: P71, P80, P90, P91, P108, P111
A8: 32 | B8: Empirical Study, Empirical Study, Empirical study, Empirical Study, Empirical Studies, Empirical Theory | C8: P40, P42, P54, P66, P75, P88 | D8: 6 | E8: 6 | G8: Empirical Study | H8: 6 | I8: P40, P42, P54, P66, P75, P88
A9: 20 | B9: Gender Balance, Gender, Gender, Gender Inequalities, gender stereotypes, gender | C9: P40, P71, P85, P88, P89, P120 | D9: 6 | E9: 6 | G9: Gender | H9: 6 | I9: P40, P71, P85, P88, P89, P120
A10: 8 | B10: Machine learning, Machine learning, MACHINE LEARNING, machine learning, machine learning | C10: P25, P68, P98, P112, P122 | D10: 5 | E10: 5
A11: 99 | B11: Case Study, Case Study, case study, Case Study, case study | C11: P53, P94, P100, P111, P123 | D11: 5 | E11: 5
A12: 87 | B12: Physical Design, decision-making, design decisions, Design, Architecture Design decisions | C12: P03, P14, P15, P45 | D12: 4 | E12: 5
A13: 47 | B13: User Feedback, Feedback Analysis, User Reviews, User Feedback, feedback | C13: P30, P63, P65, P92 | D13: 4 | E13: 5
A14: 13 | B14: Open Source, Open source, Open source, open source, Open Source | C14: P77, P84, P85, P86, P99 | D14: 5 | E14: 5
A15: 40 | B15: Privacy, Privacy Requirements, Privacy, Privacy, privacy | C15: P11, P20, P37, P63, P109 | D15: 5 | E15: 5
A16: 59 | B16: Software Architectures, Software Architecture, architecture, Software architecture, Software architecture | C16: P07, P12, P14, P45, P118 | D16: 5 | E16: 5
A17: 26 | B17: Community Smells, Community Smells, Community Smells, Community Smells, Community Smells | C17: P40, P56, P66, P75, P121 | D17: 5 | E17: 5
A18: 44 | B18: Twitter, Social Media, Facebook, Social media, Social network | C18: P25, P63, P68, P82 | D18: 4 | E18: 5
A19: 49 | B19: Covid19, COVID-19, COVID-19, Covid19 | C19: P62, P63, P83, P85 | D19: 4 | E19: 4
A20: 56 | B20: Trust, Trust, Human Trust, System Trust | C20: P41, P46 | D20: 2 | E20: 4
A21: 127 | B21: Requirements elicitation, Requirements Engineering, requirements engineering, Requirements engineering | C21: P04, P13, P52, P123 | D21: 4 | E21: 4
... A381: 379 | B381: game theory | C381: P39 | D381: 1 | E381: 1

Sheet topics_per_year
A1: ID | B1: Year | C1: ID | D1: Year | E1: ID | F1: Year | G1: ID | H1: Year | I1: ID | J1: Year | K1: ID | L1: Year | M1: ID | N1: Year
A2: Sustainability | B2: Sustainability | C2: Diversity and Inclusion | D2: Diversity and Inclusion | E2: Open Source | F2: Open Source | G2: Ethics | H2: Ethics | I2: Gender | J2: Gender | K2: Social Media | L2: Social Media | M2: Atypical Interaction Capabilities | N2: Atypical Interaction Capabilities | P2: Year | Q2: Sustainability | R2: Diversity and Inclusion | S2: Open Source | T2: Ethics | U2: Gender | V2: Social Media | W2: Atypical Interaction Capabilities
A3: P01 | B3: {=INDEX(primary_studies!D:D, MATCH(A3, primary_studies!A:A, 0))} -> 2015 | C3: P71 | D3: {=INDEX(primary_studies!D:D, MATCH(C3, primary_studies!A:A, 0))} -> 2022 | E3: P06 | F3: {=INDEX(primary_studies!D:D, MATCH(E3, primary_studies!A:A, 0))} -> 2015 | G3: P08 | H3: {=INDEX(primary_studies!D:D, MATCH(G3, primary_studies!A:A, 0))} -> 2015 | I3: P38 | J3: {=INDEX(primary_studies!D:D, MATCH(I3, primary_studies!A:A, 0))} -> 2018 | K3: P25 | L3: {=INDEX(primary_studies!D:D, MATCH(K3, primary_studies!A:A, 0))} -> 2017 | M3: P10 | N3: {=INDEX(primary_studies!D:D, MATCH(M3, primary_studies!A:A, 0))} -> 2015 | P3: 2015 | Q3: =COUNTIF(B:B, P3) -> 7 | S3: =COUNTIF(F:F, P3) -> 1 | T3: =COUNTIF(H:H, P3) -> 2 | W3: =COUNTIF(N:N, P3) -> 1
A4: P04 | B4: {=INDEX(primary_studies!D:D, MATCH(A4, primary_studies!A:A, 0))} -> 2015 | C4: P76 | D4: {=INDEX(primary_studies!D:D, MATCH(C4, primary_studies!A:A, 0))} -> 2022 | E4: P21 | F4: {=INDEX(primary_studies!D:D, MATCH(E4, primary_studies!A:A, 0))} -> 2017 | G4: P09 | H4: {=INDEX(primary_studies!D:D, MATCH(G4, primary_studies!A:A, 0))} -> 2015 | I4: P40 | J4: {=INDEX(primary_studies!D:D, MATCH(I4, primary_studies!A:A, 0))} -> 2019 | K4: P42 | L4: {=INDEX(primary_studies!D:D, MATCH(K4, primary_studies!A:A, 0))} -> 2019 | M4: P50 | N4: {=INDEX(primary_studies!D:D, MATCH(M4, primary_studies!A:A, 0))} -> 2020 | P4: 2016 | Q4: =COUNTIF(B:B, P4) -> 2
A5: P05 | B5: {=INDEX(primary_studies!D:D, MATCH(A5, primary_studies!A:A, 0))} -> 2015 | C5: P77 | D5: {=INDEX(primary_studies!D:D, MATCH(C5, primary_studies!A:A, 0))} -> 2022 | E5: P28 | F5: {=INDEX(primary_studies!D:D, MATCH(E5, primary_studies!A:A, 0))} -> 2018 | G5: P35 | H5: {=INDEX(primary_studies!D:D, MATCH(G5, primary_studies!A:A, 0))} -> 2018 | I5: P69 | J5: {=INDEX(primary_studies!D:D, MATCH(I5, primary_studies!A:A, 0))} -> 2022 | K5: P63 | L5: {=INDEX(primary_studies!D:D, MATCH(K5, primary_studies!A:A, 0))} -> 2021 | M5: P78 | N5: {=INDEX(primary_studies!D:D, MATCH(M5, primary_studies!A:A, 0))} -> 2022 | P5: 2017 | Q5: =COUNTIF(B:B, P5) -> 2 | S5: =COUNTIF(F:F, P5) -> 1 | V5: =COUNTIF(L:L, P5) -> 1
A6: P06 | B6: {=INDEX(primary_studies!D:D, MATCH(A6, primary_studies!A:A, 0))} -> 2015 | C6: P80 | D6: {=INDEX(primary_studies!D:D, MATCH(C6, primary_studies!A:A, 0))} -> 2022 | E6: P29 | F6: {=INDEX(primary_studies!D:D, MATCH(E6, primary_studies!A:A, 0))} -> 2018 | G6: P53 | H6: {=INDEX(primary_studies!D:D, MATCH(G6, primary_studies!A:A, 0))} -> 2020 | I6: P71 | J6: {=INDEX(primary_studies!D:D, MATCH(I6, primary_studies!A:A, 0))} -> 2022 | K6: P68 | L6: {=INDEX(primary_studies!D:D, MATCH(K6, primary_studies!A:A, 0))} -> 2021 | M6: P95 | N6: {=INDEX(primary_studies!D:D, MATCH(M6, primary_studies!A:A, 0))} -> 2023 | P6: 2018 | Q6: =COUNTIF(B:B, P6) -> 1 | S6: =COUNTIF(F:F, P6) -> 2 | T6: =COUNTIF(H:H, P6) -> 1 | U6: =COUNTIF(J:J, P6) -> 1
A7: P09 | B7: {=INDEX(primary_studies!D:D, MATCH(A7, primary_studies!A:A, 0))} -> 2015 | C7: P81 | D7: {=INDEX(primary_studies!D:D, MATCH(C7, primary_studies!A:A, 0))} -> 2022 | E7: P44 | F7: {=INDEX(primary_studies!D:D, MATCH(E7, primary_studies!A:A, 0))} -> 2019 | G7: P63 | H7: {=INDEX(primary_studies!D:D, MATCH(G7, primary_studies!A:A, 0))} -> 2021 | I7: P85 | J7: {=INDEX(primary_studies!D:D, MATCH(I7, primary_studies!A:A, 0))} -> 2022 | K7: P82 | L7: {=INDEX(primary_studies!D:D, MATCH(K7, primary_studies!A:A, 0))} -> 2022 | M7: P111 | N7: {=INDEX(primary_studies!D:D, MATCH(M7, primary_studies!A:A, 0))} -> 2024 | P7: 2019 | Q7: =COUNTIF(B:B, P7) -> 1 | S7: =COUNTIF(F:F, P7) -> 1 | U7: =COUNTIF(J:J, P7) -> 1 | V7: =COUNTIF(L:L, P7) -> 1
A8: P10 | B8: {=INDEX(primary_studies!D:D, MATCH(A8, primary_studies!A:A, 0))} -> 2015 | C8: P85 | D8: {=INDEX(primary_studies!D:D, MATCH(C8, primary_studies!A:A, 0))} -> 2022 | E8: P72 | F8: {=INDEX(primary_studies!D:D, MATCH(E8, primary_studies!A:A, 0))} -> 2022 | G8: P70 | H8: {=INDEX(primary_studies!D:D, MATCH(G8, primary_studies!A:A, 0))} -> 2022 | I8: P88 | J8: {=INDEX(primary_studies!D:D, MATCH(I8, primary_studies!A:A, 0))} -> 2023 | K8: P92 | L8: {=INDEX(primary_studies!D:D, MATCH(K8, primary_studies!A:A, 0))} -> 2023 | P8: 2020 | Q8: =COUNTIF(B:B, P8) -> 1 | T8: =COUNTIF(H:H, P8) -> 1 | W8: =COUNTIF(N:N, P8) -> 1
A9: P11 | B9: {=INDEX(primary_studies!D:D, MATCH(A9, primary_studies!A:A, 0))} -> 2015 | C9: P86 | D9: {=INDEX(primary_studies!D:D, MATCH(C9, primary_studies!A:A, 0))} -> 2023 | E9: P77 | F9: {=INDEX(primary_studies!D:D, MATCH(E9, primary_studies!A:A, 0))} -> 2022 | G9: P92 | H9: {=INDEX(primary_studies!D:D, MATCH(G9, primary_studies!A:A, 0))} -> 2023 | I9: P89 | J9: {=INDEX(primary_studies!D:D, MATCH(I9, primary_studies!A:A, 0))} -> 2023 | K9: P110 | L9: {=INDEX(primary_studies!D:D, MATCH(K9, primary_studies!A:A, 0))} -> 2024 | P9: 2021 | T9: =COUNTIF(H:H, P9) -> 1 | V9: =COUNTIF(L:L, P9) -> 2
A10: P13 | B10: {=INDEX(primary_studies!D:D, MATCH(A10, primary_studies!A:A, 0))} -> 2016 | C10: P88 | D10: {=INDEX(primary_studies!D:D, MATCH(C10, primary_studies!A:A, 0))} -> 2023 | E10: P81 | F10: {=INDEX(primary_studies!D:D, MATCH(E10, primary_studies!A:A, 0))} -> 2022 | G10: P97 | H10: {=INDEX(primary_studies!D:D, MATCH(G10, primary_studies!A:A, 0))} -> 2023 | I10: P90 | J10: {=INDEX(primary_studies!D:D, MATCH(I10, primary_studies!A:A, 0))} -> 2023 | K10: P114 | L10: {=INDEX(primary_studies!D:D, MATCH(K10, primary_studies!A:A, 0))} -> 2024 | P10: 2022 | R10: =COUNTIF(D:D, P10) -> 6 | S10: =COUNTIF(F:F, P10) -> 5 | T10: =COUNTIF(H:H, P10) -> 1 | U10: =COUNTIF(J:J, P10) -> 3 | V10: =COUNTIF(L:L, P10) -> 1 | W10: =COUNTIF(N:N, P10) -> 1
A11: P14 | B11: {=INDEX(primary_studies!D:D, MATCH(A11, primary_studies!A:A, 0))} -> 2016 | C11: P90 | D11: {=INDEX(primary_studies!D:D, MATCH(C11, primary_studies!A:A, 0))} -> 2023 | E11: P84 | F11: {=INDEX(primary_studies!D:D, MATCH(E11, primary_studies!A:A, 0))} -> 2022 | G11: P101 | H11: {=INDEX(primary_studies!D:D, MATCH(G11, primary_studies!A:A, 0))} -> 2023 | I11: P120 | J11: {=INDEX(primary_studies!D:D, MATCH(I11, primary_studies!A:A, 0))} -> 2024 | P11: 2023 | R11: =COUNTIF(D:D, P11) -> 8 | S11: =COUNTIF(F:F, P11) -> 3 | T11: =COUNTIF(H:H, P11) -> 3 | U11: =COUNTIF(J:J, P11) -> 3 | V11: =COUNTIF(L:L, P11) -> 1 | W11: =COUNTIF(N:N, P11) -> 1
A12: P19 | B12: {=INDEX(primary_studies!D:D, MATCH(A12, primary_studies!A:A, 0))} -> 2017 | C12: P91 | D12: {=INDEX(primary_studies!D:D, MATCH(C12, primary_studies!A:A, 0))} -> 2023 | E12: P85 | F12: {=INDEX(primary_studies!D:D, MATCH(E12, primary_studies!A:A, 0))} -> 2022 | G12: P106 | H12: {=INDEX(primary_studies!D:D, MATCH(G12, primary_studies!A:A, 0))} -> 2024 | P12: 2024 | Q12: =COUNTIF(B:B, P12) -> 3 | R12: =COUNTIF(D:D, P12) -> 2 | T12: =COUNTIF(H:H, P12) -> 1 | U12: =COUNTIF(J:J, P12) -> 1 | V12: =COUNTIF(L:L, P12) -> 2 | W12: =COUNTIF(N:N, P12) -> 1
A13: P21 | B13: {=INDEX(primary_studies!D:D, MATCH(A13, primary_studies!A:A, 0))} -> 2017 | C13: P96 | D13: {=INDEX(primary_studies!D:D, MATCH(C13, primary_studies!A:A, 0))} -> 2023 | E13: P86 | F13: {=INDEX(primary_studies!D:D, MATCH(E13, primary_studies!A:A, 0))} -> 2023
A14: P36 | B14: {=INDEX(primary_studies!D:D, MATCH(A14, primary_studies!A:A, 0))} -> 2018 | C14: P97 | D14: {=INDEX(primary_studies!D:D, MATCH(C14, primary_studies!A:A, 0))} -> 2023 | E14: P99 | F14: {=INDEX(primary_studies!D:D, MATCH(E14, primary_studies!A:A, 0))} -> 2023
A15: P45 | B15: {=INDEX(primary_studies!D:D, MATCH(A15, primary_studies!A:A, 0))} -> 2019 | C15: P103 | D15: {=INDEX(primary_studies!D:D, MATCH(C15, primary_studies!A:A, 0))} -> 2023 | E15: P104 | F15: {=INDEX(primary_studies!D:D, MATCH(E15, primary_studies!A:A, 0))} -> 2023
A16: P54 | B16: {=INDEX(primary_studies!D:D, MATCH(A16, primary_studies!A:A, 0))} -> 2020 | C16: P104 | D16: {=INDEX(primary_studies!D:D, MATCH(C16, primary_studies!A:A, 0))} -> 2023
A17: P107 | B17: {=INDEX(primary_studies!D:D, MATCH(A17, primary_studies!A:A, 0))} -> 2024 | C17: P108 | D17: {=INDEX(primary_studies!D:D, MATCH(C17, primary_studies!A:A, 0))} -> 2024
A18: P116 | B18: {=INDEX(primary_studies!D:D, MATCH(A18, primary_studies!A:A, 0))} -> 2024 | C18: P111 | D18: {=INDEX(primary_studies!D:D, MATCH(C18, primary_studies!A:A, 0))} -> 2024
A19: P118 | B19: {=INDEX(primary_studies!D:D, MATCH(A19, primary_studies!A:A, 0))} -> 2024

Sheet topics
A1: ID | B1: Category | C1: ID | D1: Keywords | F1: ID Count | G1: Keyword Count
A2: C1 | B2: Sustainability | C2: P01, P04, P05, P06, P09, P10, P11, P13, P14, P19, P21, P36, P45, P54, P107, P116, P118 | D2: sustainability, karlskrona manifesto for sustainability design, sustainability, long-term sustainability, cognitive sustainability, sustainability, sustainability design, sustainability, environmental, individual sustainability, sustainability, sustainability requirement, environmental science, environmental modelling, sustainability, sustainability, sustainability, environmental sustainability, sustainable ict, societal sustainability, social responsibility, social sustainability, social sustainability, sustainable software engineering, green software engineering, software sustainability, green ai, sustainability debt | E2: =IFERROR(__xludf.DUMMYFUNCTION("TEXTJOIN("", "", TRUE, UNIQUE(SPLIT(C2, "", ""))) "),"P01, P04, P05, P06, P09, P10, P11, P13, P14, P19, P21, P36, P45, P54, P107, P116, P118") -> P01, P04, P05, P06, P09, P10, P11, P13, P14, P19, P21, P36, P45, P54, P107, P116, P118 | F2: =IFERROR(__xludf.DUMMYFUNCTION("COUNTA(SPLIT(E2, "","")) "),17) -> 17 | G2: =IFERROR(__xludf.DUMMYFUNCTION("COUNTA(SPLIT(D2, "","")) "),28) -> 28
A3: C2 | B3: Diversity and Inclusion | C3: P71, P76, P77, P80, P81, P85, P86, P88, P90, P91, P96, P97, P103, P104, P108, P111 | D3: diversity, diverse end-users, diversity, diversity, diversity, diversity and inclusion, diversity, diversity, diversity, diversity, diversity awareness, adaptation, gender diversity, diversity, diversity, inclusion, inclusion, inclusion, inclusion, inclusive speech, inclusion, inclusion | E3: =IFERROR(__xludf.DUMMYFUNCTION("TEXTJOIN("", "", TRUE, UNIQUE(SPLIT(C3, "", ""))) "),"P71, P76, P77, P80, P81, P85, P86, P88, P90, P91, P96, P97, P103, P104, P108, P111") -> P71, P76, P77, P80, P81, P85, P86, P88, P90, P91, P96, P97, P103, P104, P108, P111 | F3: =IFERROR(__xludf.DUMMYFUNCTION("COUNTA(SPLIT(E3, "","")) "),16) -> 16 | G3: =IFERROR(__xludf.DUMMYFUNCTION("COUNTA(SPLIT(D3, "","")) "),22) -> 22
A4: C3 | B4: Research Methodology | C4: P15, P16, P40, P42, P53, P54, P55, P66, P75, P94, P96, P100, P111, P123 | D4: action research, case law analysis, case study, case study, participant studies, case study, case study, case study, empirical study, empirical study, empirical study, empirical study, empirical study, empirical studies, | E4: =IFERROR(__xludf.DUMMYFUNCTION("TEXTJOIN("", "", TRUE, UNIQUE(SPLIT(C4, "", ""))) "),"P15, P16, P40, P42, P53, P54, P55, P66, P75, P94, P96, P100, P111, P123") -> P15, P16, P40, P42, P53, P54, P55, P66, P75, P94, P96, P100, P111, P123 | F4: =IFERROR(__xludf.DUMMYFUNCTION("COUNTA(SPLIT(E4, "","")) "),14) -> 14 | G4: =IFERROR(__xludf.DUMMYFUNCTION("COUNTA(SPLIT(D4, "","")) "),15) -> 15
A5: C4 | B5: Open Source | C5: P06, P21, P28, P29, P44, P72, P77, P81, P84, P85, P86, P99, P104 | D5: open source software (oss), open source software engineering, open source software, free/open source software (foss), open-source software, open-source software analysis, open source software development, open source software, open source, open source software, open source, open source, open source, open science, open source, open-source software | E5: =IFERROR(__xludf.DUMMYFUNCTION("TEXTJOIN("", "", TRUE, UNIQUE(SPLIT(C5, "", ""))) "),"P06, P21, P28, P29, P44, P72, P77, P81, P84, P85, P86, P99, P104") -> P06, P21, P28, P29, P44, P72, P77, P81, P84, P85, P86, P99, P104 | F5: =IFERROR(__xludf.DUMMYFUNCTION("COUNTA(SPLIT(E5, "","")) "),13) -> 13 | G5: =IFERROR(__xludf.DUMMYFUNCTION("COUNTA(SPLIT(D5, "","")) "),16) -> 16
A6: C5 | B6: Ethics | C6: P08, P09, P35, P53, P63, P70, P92, P97, P101, P106 | D6: ethical concerns, ethics, principled morality, harmful micropolitics, ethics, whistleblowing, ethics, harmful terminology, socio-ethical policy, responsibility | E6: =IFERROR(__xludf.DUMMYFUNCTION("TEXTJOIN("", "", TRUE, UNIQUE(SPLIT(C6, "", ""))) "),"P08, P09, P35, P53, P63, P70, P92, P97, P101, P106") -> P08, P09, P35, P53, P63, P70, P92, P97, P101, P106 | F6: =IFERROR(__xludf.DUMMYFUNCTION("COUNTA(SPLIT(E6, "","")) "),10) -> 10 | G6: =IFERROR(__xludf.DUMMYFUNCTION("COUNTA(SPLIT(D6, "","")) "),10) -> 10
A7: C6 | B7: Gender | C7: P38, P40, P69, P71, P85, P88, P89, P90, P120 | D7: gender bias, men's orientations, gender stereotypes, gender balance, persona, gender, gender, gender inequalities, lgbtqia+, gender, female developers, women, women | E7: =IFERROR(__xludf.DUMMYFUNCTION("TEXTJOIN("","", TRUE, UNIQUE(SPLIT(C7, "",""))) "),"P38, P40, P69, P71, P85, P88, P89, P90, P120") -> P38, P40, P69, P71, P85, P88, P89, P90, P120 | F7: =IFERROR(__xludf.DUMMYFUNCTION("COUNTA(SPLIT(E7, "","")) "),9) -> 9 | G7: =IFERROR(__xludf.DUMMYFUNCTION("COUNTA(SPLIT(D7, "","")) "),13) -> 13
A8: C7 | B8: Social Media | C8: P25, P42, P63, P68, P82, P92, P110, P114 | D8: twitter, stack overflow, online forums, social media, advertising, facebook, social media, crowdsourcing, social network, reddit, online platforms, linkedin | E8: =IFERROR(__xludf.DUMMYFUNCTION("TEXTJOIN("", "", TRUE, UNIQUE(SPLIT(C8, "", ""))) "),"P25, P42, P63, P68, P82, P92, P110, P114") -> P25, P42, P63, P68, P82, P92, P110, P114 | F8: =IFERROR(__xludf.DUMMYFUNCTION("COUNTA(SPLIT(E8, "","")) "),8) -> 8 | G8: =IFERROR(__xludf.DUMMYFUNCTION("COUNTA(SPLIT(D8, "","")) "),12) -> 12
A9: C8 | B9: Education | C9: P24, P47, P49, P83, P89, P93, P102 | D9: school, whiteboard, education, individualism, education, computing education, continuing education, accessibility education, androgogy, digital literacy, primary school students | E9: =IFERROR(__xludf.DUMMYFUNCTION("TEXTJOIN("", "", TRUE, UNIQUE(SPLIT(C9, "", ""))) "),"P24, P47, P49, P83, P89, P93, P102") -> P24, P47, P49, P83, P89, P93, P102 | F9: =IFERROR(__xludf.DUMMYFUNCTION("COUNTA(SPLIT(E9, "","")) "),7) -> 7 | G9: =IFERROR(__xludf.DUMMYFUNCTION("COUNTA(SPLIT(D9, "","")) "),11) -> 11
A10: C9 | B10: Atypical Interaction Capabilities | C10: P50, P78, P111, P10, P95 | D10: intellectual disability, autism, adhd, dementia, cognitive impairment, neurodiversity | E10: =IFERROR(__xludf.DUMMYFUNCTION("TEXTJOIN("", "", TRUE, UNIQUE(SPLIT(C10, "", ""))) "),"P50, P78, P111, P10, P95") -> P50, P78, P111, P10, P95 | F10: =IFERROR(__xludf.DUMMYFUNCTION("COUNTA(SPLIT(E10, "","")) "),5) -> 5 | G10: =IFERROR(__xludf.DUMMYFUNCTION("COUNTA(SPLIT(D10, "","")) "),6) -> 6

Sheet sustainabilityprimary
A1: ID | B1: TITLE | C1: AUTHORS | D1: YEAR | F1: Social Sustainability | G1: Economic Sustainability | H1: Environmental Sustainability | I1: Technical Sustainability | J1: Social | K1: Economic | L1: Environmental | M1: Technical | N1: Focus of the contribution | O1: CITATIONS
A2: P01 | B2: Sustainability Design and Software: The Karlskrona Manifesto | C2: Christoph Becker, Ruzanna Chitchyan, Leticia Duboc, Steve Easterbrook, Birgit Penzenstadler, Norbert Seyff, Colin C. Venters | D2: 2015 | F2: Community and Social Interaction | G2: Cost Efficiency | H2: Energy Efficiency | I2: System Longevity | J2: =IF(ISTEXT(F2), 1, 0) -> 1 | N2: mindset | O2: =VLOOKUP(A2, citation_data!A:E, 6, FALSE) -> #REF!
A3: P02 | B3: Interdisciplinary Design Patterns for Socially Aware Computing | C3: Harun Baraki, Kurt Geihs, Christian Voigtmann, Axel Hoffmann, Romy Kniewel, Bjo ̈rn-Elmar Macek and Julia Zirfas | D3: 2015 | F3: User Trust and Privacy | G3: Cost Efficiency | I3: Reusability of Design Patterns | M3: =IF(ISTEXT(I3), 1, 0) -> 1 | N3: solutions | O3: =VLOOKUP(A3, citation_data!A:E, 6, FALSE) -> #REF!
A4: P03 | B4: The role of design thinking and physical prototyping in social software engineering | C4: Peter Newman, Maria Angela Ferrario, Will Simm, Stephen Forshaw, Adrian Friday, Jon Whittle | D4: 2015 | F4: Community Engagement | G4: Cost-Effective | H4: Renewable Energy Integration | I4: Scalability | J4: =IF(ISTEXT(F4), 1, 0) -> 1 | N4: skills | O4: =VLOOKUP(A4, citation_data!A:E, 6, FALSE) -> #REF!
A5: P04 | B5: On the role of value sensitive concerns in software engineering practice | C5: Balbir Barn, Ravinder Barn, Franco Raimondi​ | D5: 2015 | F5: Human Values | G5: Cost Efficiency | M5: 1 | N5: model | O5: =VLOOKUP(A5, citation_data!A:E, 6, FALSE) -> #REF!
A6: P05 | B6: Engineering sustainability through language | C6: Ruzanna Chitchyan, Walter Cazzola, Awais Rashid​​ | D6: 2015 | G6: Cost-Effective | H6: Energy Efficiency | I6: Longevity and Adaptability | M6: =IF(ISTEXT(I6), 1, 0) -> 1 | N6: programming language | O6: =VLOOKUP(A6, citation_data!A:E, 6, FALSE) -> #REF!
A7: P06 | B7: Enabling the definition and enforcement of governance rules in open source systems | C7: Javier Luis Cánovas Izquierdo, Jordi Cabot | D7: 2015 | F7: Community Engagement | G7: Cost-Effective | I7: Maintainable and Adaptable | M7: =IF(ISTEXT(I7), 1, 0) -> 1 | N7: SE process | O7: =VLOOKUP(A7, citation_data!A:E, 6, FALSE) -> #REF!
A8: P07 | B8: AppCivist: a service-oriented software platform for socially sustainable activism | C8: Animesh Pathak, Valerie Issarny, James Holston​ | D8: 2015 | F8: Community Engagement | G8: Cost-Effective | H8: Resource Efficiency | J8: =IF(ISTEXT(F8), 1, 0) -> 1 | N8: activism | O8: =VLOOKUP(A8, citation_data!A:E, 6, FALSE) -> #REF!
A9: P08 | B9: SOA4DM: applying an SOA paradigm to coordination in humanitarian disaster response | C9: Kelly Lyons, Christie Oh | D9: 2015 | F9: Improved Coordination | I9: Scalability and Flexibility | M9: =IF(ISTEXT(I9), 1, 0) -> 1 | N9: SOA | O9: =VLOOKUP(A9, citation_data!A:E, 6, FALSE) -> #REF!
A10: P09 | B10: Managing emergent ethical concerns for software engineering in society | C10: Awais Rashid, Karenza Moore, Corinne May-Chahal, Ruzanna Chitchyan | D10: 2015 | F10: Community Engagement | G10: Cost-Effective | I10: Iterative Ethical Framework | M10: =IF(ISTEXT(I10), 1, 0) -> 1 | N10: SE process | O10: =VLOOKUP(A10, citation_data!A:E, 6, FALSE) -> #REF!
A11: P10 | B11: Dementia and social sustainability: challenges for software engineering | C11: Alistair Sutcliffe, Paul Rayson, Chris Bull, Pete Sawyer | D11: 2015 | F11: Support for Social Communities(Dementia patients in this case) | G11: Reducing Healthcare Costs | I11: Long-term Use and Adaptation | M11: =IF(ISTEXT(I11), 1, 0) -> 1 | N11: SE challenges | O11: =VLOOKUP(A11, citation_data!A:E, 6, FALSE) -> #REF!
A12: P11 | B12: Cognitively sustainable ICT with ubiquitous mobile services: challenges and opportunities | C12: Marcus Jägemar, Gordana Dodig Crnkovic​ | D12: 2015 | F12: Privacy, Work-Life Balance | J12: =IF(ISTEXT(F12), 1, 0) -> 1 | N12: cognition | O12: =VLOOKUP(A12, citation_data!A:E, 6, FALSE) -> #REF!
A13: P12 | B13: Software energy profiling: comparing releases of a software product | C13: Erik A. Jagroep, Jan Martijn van der Werf, Giuseppe Procaccianti, Patricia Lago, Sjaak Brinkkemper, Leen Blom, Rob van Vliet | D13: 2016 | G13: Resource Efficiency | H13: Energy Efficiency | M13: 1 | N13: profiling method | O13: =VLOOKUP(A13, citation_data!A:E, 6, FALSE) -> #REF!
A14: P13 | B14: Sustainability design in requirements engineering: state of practice | C14: Ruzanna Chitchyan, Walter Cazzola, Awais Rashid | D14: 2016 | G14: Cost Considerations | H14: Resource Efficiency | J14: 1 | N14: skills and organisation priorities | O14: =VLOOKUP(A14, citation_data!A:E, 6, FALSE) -> #REF!
A15: P14 | B15: Sustainability debt: a portfolio-based approach for evaluating sustainability requirements in architectures | C15: Javier Garbajosa, José Ángel Sanz, Mikael Svahnberg, Jan Bosch | D15: 2016 | F15: Societal Contribution | G15: Cost-Effective | H15: Energy Efficiency | I15: Maintainability | M15: =IF(ISTEXT(I15), 1, 0) -> 1 | N15: estimation | O15: =VLOOKUP(A15, citation_data!A:E, 6, FALSE) -> #REF!
A16: P15 | B16: Values-first SE: research principles in practice | C16: Maria Paasivaara, Casper Lassenius, Steven Fraser, Jürgen Münch, Kari Systä | D16: 2016 | F16: Human Values | G16: Cost-Efficiency | I16: Maintainable and Adaptable | M16: =IF(ISTEXT(I16), 1, 0) -> 1 | N16: SE process | O16: =VLOOKUP(A16, citation_data!A:E, 6, FALSE) -> #REF!
A17: P16 | B17: A guided tour of the legal implications of software cloning | C17: Paolo Ciancarini, Daniel Russo, Alberto Sillitti, Giancarlo Succi | D17: 2016 | G17: Market Competition | J17: 1 | N17: law | O17: =VLOOKUP(A17, citation_data!A:E, 6, FALSE) -> #REF!
A18: P17 | B18: Engineering software assemblies for participatory democracy: the participatory budgeting use case | C18: James Holston, Valérie Issarny, Cristhian Parra | D18: 2016 | F18: Community Engagement | G18: effective use of resources by Participatory Budgeting | I18: Integration and Flexibility | M18: =IF(ISTEXT(I18), 1, 0) -> 1 | N18: SE (process + product) | O18: =VLOOKUP(A18, citation_data!A:E, 6, FALSE) -> #REF!
A19: P18 | B19: Software engineering and policy | C19: Anthony Finkelstein | D19: 2016 | F19: Health | G19: Economic Prosperity | H19: Energy Policy | M19: 1 | N19: embed policy in SE | O19: =VLOOKUP(A19, citation_data!A:E, 6, FALSE) -> #REF!
A20: P19 | B20: Characterising Sustainability Requirements: A New Species Red Herring or Just an Odd Fish? | C20: Colin C. Venters, Norbert Seyff, Christoph Becker, Stefanie Betz, Ruzanna Chitchyan, Leticia Duboc, Dan McIntyre, Birgit Penzenstadler | D20: 2017 | F20: Societal Impact | G20: Cost Efficiency | H20: Energy Efficiency | I20: Maintainability | M20: =IF(ISTEXT(I20), 1, 0) -> 1 | N20: SE (RE) | O20: =VLOOKUP(A20, citation_data!A:E, 6, FALSE) -> #REF!
A21: P20 | B21: Privacy Requirements: Present & Future | C21: Pauline Anthonysamy, Awais Rashid, Ruzanna Chitchyan | D21: 2017 | F21: Societal Impact | I21: Maintainability | M21: =IF(ISTEXT(I21), 1, 0) -> 1 | N21: SE (RE) and process | O21: =VLOOKUP(A21, citation_data!A:E, 6, FALSE) -> #REF!
A22: P21 | B22: Preparing Research Projects for Sustainable Software Engineering in Society | C22: Dominik Renzel, István Koren, Ralf Klamma, Matthias Jarke | D22: 2017 | F22: sustainable community | I22: Maintainability | M22: =IF(ISTEXT(I22), 1, 0) -> 1 | N22: SE process | O22: =VLOOKUP(A22, citation_data!A:E, 6, FALSE) -> #REF!
A23: P22 | B23: Understanding How Software Can Support the Needs of Family Caregivers for Patients with Severe Conditions | C23: Angela di Fiore, Francesco Ceschel, Francesca Fiore, Marcos Baez, Fabio Casati, Giampaolo Armellin | D23: 2017 | F23: Community Building | I23: Maintainability | M23: =IF(ISTEXT(I23), 1, 0) -> 1 | N23: SE | O23: =VLOOKUP(A23, citation_data!A:E, 6, FALSE) -> #REF!
A24: P23 | B24: Portinari: A Data Exploration Tool to Personalize Cervical Cancer Screening | C24: Sagar Sen, Manoel Horta Ribeiro, Raquel C. de Melo Minardi, Wagner Meira Jr., Mari Nygård | D24: 2017 | F24: Community Health | G24: Cost Efficiency | M24: 1 | N24: tool | O24: =VLOOKUP(A24, citation_data!A:E, 6, FALSE) -> #REF!
A25: P24 | B25: Deploying Large Scale School Census Hub: An Experience Report | C25: Andrew Kinai, Juliet Mutahi, Karumba Samuel, Komminist Weldemariam | D25: 2017 | F25: Community Building | G25: Cost Efficiency | I25: Maintainability | M25: =IF(ISTEXT(I25), 1, 0) -> 1 | N25: data collection | O25: =VLOOKUP(A25, citation_data!A:E, 6, FALSE) -> #REF!
A26: P25 | B26: Crowdsourced Exploration of Mobile App Features: A Case Study of the Fort McMurray Wildfire | C26: Maleknaz Nayebi, Rachel Quapp, Guenther Ruhe, Mahshid Marbouti, Frank Maurer | D26: 2017 | F26: Community Building | I26: continuously analyze and integrate | M26: =IF(ISTEXT(I26), 1, 0) -> 1 | N26: method/tool | O26: =VLOOKUP(A26, citation_data!A:E, 6, FALSE) -> #REF!
A27: P26 | B27: Leveraging the Service Bus Paradigm for Computer-Mediated Social Communication Interoperability | C27: Rafael Angarita, Nikolaos Georgantas, Cristhian Parra, James Holston, Valérie Issarny | D27: 2017 | F27: Community Building | M27: 1 | N27: middleware | O27: =VLOOKUP(A27, citation_data!A:E, 6, FALSE) -> #REF!
A28: P27 | B28: Awakening Awareness on Energy Consumption in Software Engineering | C28: Erik Jagroep, Jordy Broekman, Jan Martijn E.M. van der Werf, Sjaak Brinkkemper, Patricia Lago, Leen Blom, Rob van Vliet | D28: 2017 | G28: Cost Efficiency | H28: Energy Efficiency | I28: integration of energy consumption considerations into the software development lifecycle | L28: =IF(ISTEXT(H28), 1, 0) -> 1 | N28: environmental awareness | O28: =VLOOKUP(A28, citation_data!A:E, 6, FALSE) -> #REF!
A29: P28 | B29: Software Heritage: Why and How We Collect, Preserve and Share All the Software Source Code | C29: Roberto Di Cosmo | D29: 2018 | F29: Cultural Preservation | G29: Cost Efficiency | I29: Adaptability | M29: =IF(ISTEXT(I29), 1, 0) -> 1 | N29: platform | O29: =VLOOKUP(A29, citation_data!A:E, 6, FALSE) -> #REF!
A30: P29 | B30: The Role of Foundations in Open Source Projects | C30: Javier Luis Cánovas Izquierdo, Jordi Cabot | D30: 2018 | F30: Community Building | I30: Maintainability | J30: =IF(ISTEXT(F30), 1, 0) -> 1 | N30: role of foundations | O30: =VLOOKUP(A30, citation_data!A:E, 6, FALSE) -> #REF!
A31: P30 | B31: User Feedback in the App Store: A Cross-Cultural Study | C31: Emitza Guzman, Luís Oliveira, Yves Steiner, Laura C. Wagner, Martin Glinz | D31: 2018 | F31: Inclusivity | I31: Adaptability | J31: =IF(ISTEXT(F31), 1, 0) -> 1 | N31: user feedback | O31: =VLOOKUP(A31, citation_data!A:E, 6, FALSE) -> #REF!
A32: P31 | B32: Assistive Computing: A Human-Centered Approach to Developing Computing Support for Cognition | C32: Simon Harper, Sean Bechhofer, Carsten Maple, Colin P. Perera, Dave Green, Andy Brown | D32: 2018 | F32: User-Centered Design | G32: Resource Efficiency | I32: Maintainable and Adaptable | M32: =IF(ISTEXT(I32), 1, 0) -> 1 | N32: SE process | O32: =VLOOKUP(A32, citation_data!A:E, 6, FALSE) -> #REF!
A33: P32 | B33: Agile Development for Vulnerable Populations: Lessons Learned and Recommendations | C33: Marcos Baez, Fabio Casati | D33: 2018 | F33: Human Centered Design | G33: Cost of Errors(Cost Efficiency) | I33: Adaptability | M33: =IF(ISTEXT(I33), 1, 0) -> 1 | N33: SE process | O33: =VLOOKUP(A33, citation_data!A:E, 6, FALSE) -> #REF!
A34: P33 | B34: Digitalization of Swedish Government Agencies - A Perspective Through the Lens of a Software Development Census | C34: Markus Borg, omas Olsson, Ulrik Franke, Sa ̈ıd Assar | D34: 2018 | F34: Community Engagement | G34: Cost Efficiency | I34: Maintainability | M34: =IF(ISTEXT(I34), 1, 0) -> 1 | N34: SE process | O34: =VLOOKUP(A34, citation_data!A:E, 6, FALSE) -> #REF!
A35: P34 | B35: Contracting Agile Developments for Mission Critical Systems in the Public Sector | C35: Daniel Russo, Gerolamo Taccogna, Paolo Ciancarini, Angelo Messina, Giancarlo Succi | D35: 2018 | G35: Cost Efficiency | I35: Maintainability | M35: =IF(ISTEXT(I35), 1, 0) -> 1 | N35: SE process | O35: =VLOOKUP(A35, citation_data!A:E, 6, FALSE) -> #REF!
A36: P35 | B36: Resolving Ambiguities in Regulations: Towards Achieving the Kohlbergian Stage of Principled Morality | C36: Smita Ghaisas, Abhishek Sainani, Preethu Rose | D36: 2018 | F36: Fairness | G36: Cost Efficiency | I36: Automation and Deep Learning | M36: =IF(ISTEXT(I36), 1, 0) -> 1 | N36: policy embedding tool | O36: =VLOOKUP(A36, citation_data!A:E, 6, FALSE) -> #REF!
A37: P36 | B37: SE in ES: Opportunities for Software Engineering and Cloud Computing in Environmental Science | C37: W.A. Simm, F. Samreen, R. Bassett, M.A. Ferrario, G. Blair, J. Whittle, P.J. Young | D37: 2018 | F37: Accessibility | G37: Cost Efficiency | H37: resource efficiency | I37: Adaptability | M37: =IF(ISTEXT(I37), 1, 0) -> 1 | N37: cloud | O37: =VLOOKUP(A37, citation_data!A:E, 6, FALSE) -> #REF!
A38: P37 | B38: Towards a Unified Conceptual Model for Surveillance Theories: "We Shall Meet in the Place Where There is no Darkness" - 1984, George Orwell | C38: Balbir S. Barn, Ravinder Barn | D38: 2018 | F38: Privacy | I38: Adaptability | M38: =IF(ISTEXT(I38), 1, 0) -> 1 | N38: IS design | O38: =VLOOKUP(A38, citation_data!A:E, 6, FALSE) -> #REF!
A39: P38 | B39: Competence-Confidence Gap: A Threat to Female Developers' Contribution on GitHub | C39: Zhendong Wang, Yi Wang, David Redmiles | D39: 2018 | F39: addressing gender gaps | G39: Maximizing Impact and Growth | J39: =IF(ISTEXT(F39), 1, 0) -> 1 | N39: gender gap | O39: =VLOOKUP(A39, citation_data!A:E, 6, FALSE) -> #REF!
A40: P39 | B40: Digital Ecclesia: Towards an Online Direct-Democracy Framework | C40: Dionysis Athanasopoulos | D40: 2018 | F40: inclusivity | G40: Cost Efficiency | I40: Scalability and Flexibility | M40: =IF(ISTEXT(I40), 1, 0) -> 1 | N40: platform | O40: =VLOOKUP(A40, citation_data!A:E, 6, FALSE) -> #REF!
...

Sheet sustainability_enabled
B1: TITLE | C1: AUTHORS | D1: YEAR | F1: Social Sustainability | G1: Economic Sustainability | H1: Environmental Sustainability | I1: Technical Sustainability | J1: Social | K1: Economic | L1: Environmental | M1: Technical
A2: P01 | B2: Sustainability Design and Software: The Karlskrona Manifesto | C2: Christoph Becker, Ruzanna Chitchyan, Leticia Duboc, Steve Easterbrook, Birgit Penzenstadler, Norbert Seyff, Colin C. Venters | D2: 2015 | F2: Community and Social Interaction | G2: Cost Efficiency | H2: Energy Efficiency | I2: System Longevity | J2: =IF(ISTEXT(F2), 1, 0) -> 1 | K2: =IF(ISTEXT(G2), 1, 0) -> 1 | L2: =IF(ISTEXT(H2), 1, 0) -> 1 | M2: =IF(ISTEXT(I2), 1, 0) -> 1 | N2: =SUM(J2:M2) -> 4
A3: P02 | B3: Interdisciplinary Design Patterns for Socially Aware Computing | C3: Harun Baraki, Kurt Geihs, Christian Voigtmann, Axel Hoffmann, Romy Kniewel, Bjo ̈rn-Elmar Macek and Julia Zirfas | D3: 2015 | F3: User Trust and Privacy | G3: Cost Efficiency | I3: Reusability of Design Patterns | J3: =IF(ISTEXT(F3), 1, 0) -> 1 | K3: =IF(ISTEXT(G3), 1, 0) -> 1 | L3: =IF(ISTEXT(H3), 1, 0) -> 0 | M3: =IF(ISTEXT(I3), 1, 0) -> 1 | N3: =SUM(J3:M3) -> 3
A4: P03 | B4: The role of design thinking and physical prototyping in social software engineering | C4: Peter Newman, Maria Angela Ferrario, Will Simm, Stephen Forshaw, Adrian Friday, Jon Whittle | D4: 2015 | F4: Community Engagement | G4: Cost-Effective | H4: Renewable Energy Integration | I4: Scalability | J4: =IF(ISTEXT(F4), 1, 0) -> 1 | K4: =IF(ISTEXT(G4), 1, 0) -> 1 | L4: =IF(ISTEXT(H4), 1, 0) -> 1 | M4: =IF(ISTEXT(I4), 1, 0) -> 1 | N4: =SUM(J4:M4) -> 4
A5: P04 | B5: On the role of value sensitive concerns in software engineering practice | C5: Balbir Barn, Ravinder Barn, Franco Raimondi​ | D5: 2015 | F5: Human Values | G5: Cost Efficiency | J5: =IF(ISTEXT(F5), 1, 0) -> 1 | K5: =IF(ISTEXT(G5), 1, 0) -> 1 | L5: =IF(ISTEXT(H5), 1, 0) -> 0 | M5: =IF(ISTEXT(I5), 1, 0) -> 0 | N5: =SUM(J5:M5) -> 2
A6: P05 | B6: Engineering sustainability through language | C6: Ruzanna Chitchyan, Walter Cazzola, Awais Rashid​​ | D6: 2015 | G6: Cost-Effective | H6: Energy Efficiency | I6: Longevity and Adaptability | J6: =IF(ISTEXT(F6), 1, 0) -> 0 | K6: =IF(ISTEXT(G6), 1, 0) -> 1 | L6: =IF(ISTEXT(H6), 1, 0) -> 1 | M6: =IF(ISTEXT(I6), 1, 0) -> 1 | N6: =SUM(J6:M6) -> 3
A7: P06 | B7: Enabling the definition and enforcement of governance rules in open source systems | C7: Javier Luis Cánovas Izquierdo, Jordi Cabot | D7: 2015 | F7: Community Engagement | G7: Cost-Effective | I7: Maintainable and Adaptable | J7: =IF(ISTEXT(F7), 1, 0) -> 1 | K7: =IF(ISTEXT(G7), 1, 0) -> 1 | L7: =IF(ISTEXT(H7), 1, 0) -> 0 | M7: =IF(ISTEXT(I7), 1, 0) -> 1 | N7: =SUM(J7:M7) -> 3
A8: P07 | B8: AppCivist: a service-oriented software platform for socially sustainable activism | C8: Animesh Pathak, Valerie Issarny, James Holston​ | D8: 2015 | F8: Community Engagement | G8: Cost-Effective | H8: Resource Efficiency | J8: =IF(ISTEXT(F8), 1, 0) -> 1 | K8: =IF(ISTEXT(G8), 1, 0) -> 1 | L8: =IF(ISTEXT(H8), 1, 0) -> 1 | M8: =IF(ISTEXT(I8), 1, 0) -> 0 | N8: =SUM(J8:M8) -> 3
A9: P08 | B9: SOA4DM: applying an SOA paradigm to coordination in humanitarian disaster response | C9: Kelly Lyons, Christie Oh | D9: 2015 | F9: Improved Coordination | I9: Scalability and Flexibility | J9: =IF(ISTEXT(F9), 1, 0) -> 1 | K9: =IF(ISTEXT(G9), 1, 0) -> 0 | L9: =IF(ISTEXT(H9), 1, 0) -> 0 | M9: =IF(ISTEXT(I9), 1, 0) -> 1 | N9: =SUM(J9:M9) -> 2
A10: P09 | B10: Managing emergent ethical concerns for software engineering in society | C10: Awais Rashid, Karenza Moore, Corinne May-Chahal, Ruzanna Chitchyan | D10: 2015 | F10: Community Engagement | G10: Cost-Effective | I10: Iterative Ethical Framework | J10: =IF(ISTEXT(F10), 1, 0) -> 1 | K10: =IF(ISTEXT(G10), 1, 0) -> 1 | L10: =IF(ISTEXT(H10), 1, 0) -> 0 | M10: =IF(ISTEXT(I10), 1, 0) -> 1 | N10: =SUM(J10:M10) -> 3
